Workbook

Sheet ReadMe
A1: SPECTRE walkthrough: "good night sweet prince" (Hamlet, Act 5)
A3: Toy world, sized for hand-checking:
A4: tokenizer: whitespace, no marker -> 4 tokens: good(m=0) night(m=1) sweet(m=2) prince(m=3)
A5: L_max = 10 code points (English) -> omega floor = 180/10 = 18 deg
A6: K = 3 lenses: 162 / 54 / 18 deg per step (ratio exactly 1/3)
A7: d_model = 8 -> 4 pairs -> 4 theta speeds: 162 / 66.59 / 27.37 / 11.25 (floor 180/16, max_slots=16)
A8: English = 1 byte per character, so each letter owns ONE box; collisions come only from repeated letters.
A10: Pipeline, sheet by sheet:
A11: Ladder the only design inputs (blue). Everything else derives.
A12: good/night/sweet/prince per-token codec: angles -> arrows -> box sums -> |arrow| -> energy -> NORM -> normalized components
A13: Squeeze 78 features x learned W(78x8, blue "random init") -> 8-dim embedding per token
A14: Twist each embedding read as 4 arrows; arrow j rotated by theta_j x slot m
... A18: Every number is a live formula except blue inputs; change Ladder inputs or W and all sheets re-derive.

Sheet Ladder
A1: Design inputs (blue). Two ladders: omega (inside tokens), theta (across slots).
A3: w_max (x pi) | B3: 0.9
A4: L_max (longest token, cp) | B4: 10
A5: w_min (x pi) = 1/L_max | B5: =1/B4 -> 0.1
A6: K (lenses) | B6: 3
A7: r_omega | B7: =(B5/B3)^(1/(B6-1)) -> 0.33333333
A9: max_slots (sequence) | B9: 16
A10: theta_min (x pi) = 1/max_slots | B10: =1/B9 -> 0.0625
A11: pairs (d_model/2) | B11: 4
A12: r_theta | B12: =(B10/B3)^(1/(B11-1)) -> 0.41103535
A14: omega ladder (deg/step)
A15: L0 | B15: =180*$B$3*$B$7^0 -> 162
A16: L1 | B16: =180*$B$3*$B$7^1 -> 54
A17: L2 | B17: =180*$B$3*$B$7^2 -> 18
A19: theta ladder (deg/slot)
A20: th0 | B20: =180*$B$3*$B$12^0 -> 162
A21: th1 | B21: =180*$B$3*$B$12^1 -> 66.587726
A22: th2 | B22: =180*$B$3*$B$12^2 -> 27.369909
A23: th3 | B23: =180*$B$3*$B$12^3 -> 11.25

Sheet good
A1: Token "good" (slot m=0, 4 cp). Codec, every step.
A2: angle -> Re/Im -> box sums -> |arrow| -> energy -> NORM -> NORMALIZED components (these feed the Squeeze).
C5: ANGLES = -p x step | G5: Re = COS | K5: Im = SIN | O5: BOX SUMS | U5: |arrow| | X5: energy | Y5: NORMALIZED components = (Re,Im)/NORM
A6: lens | B6: step | C6: g p=0 | D6: o p=1 | E6: o p=2 | F6: d p=3 | G6: g p=0 | H6: o p=1 | I6: o p=2 | J6: d p=3 | K6: g p=0 | L6: o p=1 | M6: o p=2 | N6: d p=3 | O6: d Re | P6: d Im | Q6: g Re | R6: g Im | S6: o Re | T6: o Im | U6: d | V6: g | W6: o | X6: sum|a|^2 | Y6: d Re | Z6: d Im | AA6: g Re | AB6: g Im | AC6: o Re | AD6: o Im
O7: p=3 | Q7: p=0 | S7: p=1,2
A8: L0 | B8: =ROUND(Ladder!$B$15,2) -> 162 | C8: =-0*Ladder!$B$15 -> 0 | D8: =-1*Ladder!$B$15 -> -162 | E8: =-2*Ladder!$B$15 -> -324 | F8: =-3*Ladder!$B$15 -> -486 | G8: =COS(RADIANS(C8)) -> 1 | H8: =COS(RADIANS(D8)) -> -0.95105652 | I8: =COS(RADIANS(E8)) -> 0.80901699 | J8: =COS(RADIANS(F8)) -> -0.58778525 | K8: =SIN(RADIANS(C8)) -> 0 | L8: =SIN(RADIANS(D8)) -> -0.30901699 | M8: =SIN(RADIANS(E8)) -> 0.58778525 | N8: =SIN(RADIANS(F8)) -> -0.80901699 | O8: =J8 -> -0.58778525 | P8: =N8 -> -0.80901699 | Q8: =G8 -> 1 | R8: =K8 -> 0 | S8: =H8+I8 -> -0.14203952 | T8: =L8+M8 -> 0.27876826 | U8: =SQRT(O8^2+P8^2) -> 1 | V8: =SQRT(Q8^2+R8^2) -> 1 | W8: =SQRT(S8^2+T8^2) -> 0.31286893 | X8: =SUMSQ(U8:W8) -> 2.097887 | Y8: =O8/$B$13 -> -0.16193248 | Z8: =P8/$B$13 -> -0.22288094 | AA8: =Q8/$B$13 -> 0.27549599 | AB8: =R8/$B$13 -> 0 | AC8: =S8/$B$13 -> -0.039131319 | AD8: =T8/$B$13 -> 0.076799538
A9: L1 | B9: =ROUND(Ladder!$B$16,2) -> 54 | C9: =-0*Ladder!$B$16 -> 0 | D9: =-1*Ladder!$B$16 -> -54 | E9: =-2*Ladder!$B$16 -> -108 | F9: =-3*Ladder!$B$16 -> -162 | G9: =COS(RADIANS(C9)) -> 1 | H9: =COS(RADIANS(D9)) -> 0.58778525 | I9: =COS(RADIANS(E9)) -> -0.30901699 | J9: =COS(RADIANS(F9)) -> -0.95105652 | K9: =SIN(RADIANS(C9)) -> 0 | L9: =SIN(RADIANS(D9)) -> -0.80901699 | M9: =SIN(RADIANS(E9)) -> -0.95105652 | N9: =SIN(RADIANS(F9)) -> -0.30901699 | O9: =J9 -> -0.95105652 | P9: =N9 -> -0.30901699 | Q9: =G9 -> 1 | R9: =K9 -> 0 | S9: =H9+I9 -> 0.27876826 | T9: =L9+M9 -> -1.7600735 | U9: =SQRT(O9^2+P9^2) -> 1 | V9: =SQRT(Q9^2+R9^2) -> 1 | W9: =SQRT(S9^2+T9^2) -> 1.782013 | X9: =SUMSQ(U9:W9) -> 5.1755705 | Y9: =O9/$B$13 -> -0.26201226 | Z9: =P9/$B$13 -> -0.085132943 | AA9: =Q9/$B$13 -> 0.27549599 | AB9: =R9/$B$13 -> 0 | AC9: =S9/$B$13 -> 0.076799538 | AD9: =T9/$B$13 -> -0.4848932
A10: L2 | B10: =ROUND(Ladder!$B$17,2) -> 18 | C10: =-0*Ladder!$B$17 -> 0 | D10: =-1*Ladder!$B$17 -> -18 | E10: =-2*Ladder!$B$17 -> -36 | F10: =-3*Ladder!$B$17 -> -54 | G10: =COS(RADIANS(C10)) -> 1 | H10: =COS(RADIANS(D10)) -> 0.95105652 | I10: =COS(RADIANS(E10)) -> 0.80901699 | J10: =COS(RADIANS(F10)) -> 0.58778525 | K10: =SIN(RADIANS(C10)) -> 0 | L10: =SIN(RADIANS(D10)) -> -0.30901699 | M10: =SIN(RADIANS(E10)) -> -0.58778525 | N10: =SIN(RADIANS(F10)) -> -0.80901699 | O10: =J10 -> 0.58778525 | P10: =N10 -> -0.80901699 | Q10: =G10 -> 1 | R10: =K10 -> 0 | S10: =H10+I10 -> 1.7600735 | T10: =L10+M10 -> -0.89680225 | U10: =SQRT(O10^2+P10^2) -> 1 | V10: =SQRT(Q10^2+R10^2) -> 1 | W10: =SQRT(S10^2+T10^2) -> 1.9753767 | X10: =SUMSQ(U10:W10) -> 5.902113 | Y10: =O10/$B$13 -> 0.16193248 | Z10: =P10/$B$13 -> -0.22288094 | AA10: =Q10/$B$13 -> 0.27549599 | AB10: =R10/$B$13 -> 0 | AC10: =S10/$B$13 -> 0.4848932 | AD10: =T10/$B$13 -> -0.24706542
A12: total energy | B12: =SUM(X8:X10) -> 13.175571
A13: NORM | B13: =SQRT(B12) -> 3.6298169
A14: CHECK SUMSQ(norm comps)=1 | B14: =SUMSQ(Y8:AD10) -> 1

Sheet night
A1: Token "night" (slot m=1, 5 cp). Codec, every step.
A2: angle -> Re/Im -> box sums -> |arrow| -> energy -> NORM -> NORMALIZED components (these feed the Squeeze).
C5: ANGLES = -p x step | H5: Re = COS | M5: Im = SIN | R5: BOX SUMS | AB5: |arrow| | AG5: energy | AH5: NORMALIZED components = (Re,Im)/NORM
A6: lens | B6: step | C6: n p=0 | D6: i p=1 | E6: g p=2 | F6: h p=3 | G6: t p=4 | H6: n p=0 | I6: i p=1 | J6: g p=2 | K6: h p=3 | L6: t p=4 | M6: n p=0 | N6: i p=1 | O6: g p=2 | P6: h p=3 | Q6: t p=4 | R6: g Re | S6: g Im | T6: h Re | U6: h Im | V6: i Re | W6: i Im | X6: n Re | Y6: n Im | Z6: t Re | AA6: t Im | AB6: g | AC6: h | AD6: i | AE6: n | AF6: t | AG6: sum|a|^2 | AH6: g Re | AI6: g Im | AJ6: h Re | AK6: h Im | AL6: i Re | AM6: i Im | AN6: n Re | AO6: n Im | AP6: t Re | AQ6: t Im
R7: p=2 | T7: p=3 | V7: p=1 | X7: p=0 | Z7: p=4
A8: L0 | B8: =ROUND(Ladder!$B$15,2) -> 162 | C8: =-0*Ladder!$B$15 -> 0 | D8: =-1*Ladder!$B$15 -> -162 | E8: =-2*Ladder!$B$15 -> -324 | F8: =-3*Ladder!$B$15 -> -486 | G8: =-4*Ladder!$B$15 -> -648 | H8: =COS(RADIANS(C8)) -> 1 | I8: =COS(RADIANS(D8)) -> -0.95105652 | J8: =COS(RADIANS(E8)) -> 0.80901699 | K8: =COS(RADIANS(F8)) -> -0.58778525 | L8: =COS(RADIANS(G8)) -> 0.30901699 | M8: =SIN(RADIANS(C8)) -> 0 | N8: =SIN(RADIANS(D8)) -> -0.30901699 | O8: =SIN(RADIANS(E8)) -> 0.58778525 | P8: =SIN(RADIANS(F8)) -> -0.80901699 | Q8: =SIN(RADIANS(G8)) -> 0.95105652 | R8: =J8 -> 0.80901699 | S8: =O8 -> 0.58778525 | T8: =K8 -> -0.58778525 | U8: =P8 -> -0.80901699 | V8: =I8 -> -0.95105652 | W8: =N8 -> -0.30901699 | X8: =H8 -> 1 | Y8: =M8 -> 0 | Z8: =L8 -> 0.30901699 | AA8: =Q8 -> 0.95105652 | AB8: =SQRT(R8^2+S8^2) -> 1 | AC8: =SQRT(T8^2+U8^2) -> 1 | AD8: =SQRT(V8^2+W8^2) -> 1 | AE8: =SQRT(X8^2+Y8^2) -> 1 | AF8: =SQRT(Z8^2+AA8^2) -> 1 | AG8: =SUMSQ(AB8:AF8) -> 5 | AH8: =R8/$B$13 -> 0.20888729 | AI8: =S8/$B$13 -> 0.1517655 | AJ8: =T8/$B$13 -> -0.1517655 | AK8: =U8/$B$13 -> -0.20888729 | AL8: =V8/$B$13 -> -0.24556174 | AM8: =W8/$B$13 -> -0.079787845 | AN8: =X8/$B$13 -> 0.25819889 | AO8: =Y8/$B$13 -> 0 | ... AQ8: =AA8/$B$13 -> 0.24556174
A9: L1 | B9: =ROUND(Ladder!$B$16,2) -> 54 | C9: =-0*Ladder!$B$16 -> 0 | D9: =-1*Ladder!$B$16 -> -54 | E9: =-2*Ladder!$B$16 -> -108 | F9: =-3*Ladder!$B$16 -> -162 | G9: =-4*Ladder!$B$16 -> -216 | H9: =COS(RADIANS(C9)) -> 1 | I9: =COS(RADIANS(D9)) -> 0.58778525 | J9: =COS(RADIANS(E9)) -> -0.30901699 | K9: =COS(RADIANS(F9)) -> -0.95105652 | L9: =COS(RADIANS(G9)) -> -0.80901699 | M9: =SIN(RADIANS(C9)) -> 0 | N9: =SIN(RADIANS(D9)) -> -0.80901699 | O9: =SIN(RADIANS(E9)) -> -0.95105652 | P9: =SIN(RADIANS(F9)) -> -0.30901699 | Q9: =SIN(RADIANS(G9)) -> 0.58778525 | R9: =J9 -> -0.30901699 | S9: =O9 -> -0.95105652 | T9: =K9 -> -0.95105652 | U9: =P9 -> -0.30901699 | V9: =I9 -> 0.58778525 | W9: =N9 -> -0.80901699 | X9: =H9 -> 1 | Y9: =M9 -> 0 | Z9: =L9 -> -0.80901699 | AA9: =Q9 -> 0.58778525 | AB9: =SQRT(R9^2+S9^2) -> 1 | AC9: =SQRT(T9^2+U9^2) -> 1 | AD9: =SQRT(V9^2+W9^2) -> 1 | AE9: =SQRT(X9^2+Y9^2) -> 1 | AF9: =SQRT(Z9^2+AA9^2) -> 1 | AG9: =SUMSQ(AB9:AF9) -> 5 | AH9: =R9/$B$13 -> -0.079787845 | AI9: =S9/$B$13 -> -0.24556174 | AJ9: =T9/$B$13 -> -0.24556174 | AK9: =U9/$B$13 -> -0.079787845 | AL9: =V9/$B$13 -> 0.1517655 | AM9: =W9/$B$13 -> -0.20888729 | AN9: =X9/$B$13 -> 0.25819889 | AO9: =Y9/$B$13 -> 0 | ... AQ9: =AA9/$B$13 -> 0.1517655
A10: L2 | B10: =ROUND(Ladder!$B$17,2) -> 18 | C10: =-0*Ladder!$B$17 -> 0 | D10: =-1*Ladder!$B$17 -> -18 | E10: =-2*Ladder!$B$17 -> -36 | F10: =-3*Ladder!$B$17 -> -54 | G10: =-4*Ladder!$B$17 -> -72 | H10: =COS(RADIANS(C10)) -> 1 | I10: =COS(RADIANS(D10)) -> 0.95105652 | J10: =COS(RADIANS(E10)) -> 0.80901699 | K10: =COS(RADIANS(F10)) -> 0.58778525 | L10: =COS(RADIANS(G10)) -> 0.30901699 | M10: =SIN(RADIANS(C10)) -> 0 | N10: =SIN(RADIANS(D10)) -> -0.30901699 | O10: =SIN(RADIANS(E10)) -> -0.58778525 | P10: =SIN(RADIANS(F10)) -> -0.80901699 | Q10: =SIN(RADIANS(G10)) -> -0.95105652 | R10: =J10 -> 0.80901699 | S10: =O10 -> -0.58778525 | T10: =K10 -> 0.58778525 | U10: =P10 -> -0.80901699 | V10: =I10 -> 0.95105652 | W10: =N10 -> -0.30901699 | X10: =H10 -> 1 | Y10: =M10 -> 0 | Z10: =L10 -> 0.30901699 | AA10: =Q10 -> -0.95105652 | AB10: =SQRT(R10^2+S10^2) -> 1 | AC10: =SQRT(T10^2+U10^2) -> 1 | AD10: =SQRT(V10^2+W10^2) -> 1 | AE10: =SQRT(X10^2+Y10^2) -> 1 | AF10: =SQRT(Z10^2+AA10^2) -> 1 | AG10: =SUMSQ(AB10:AF10) -> 5 | AH10: =R10/$B$13 -> 0.20888729 | AI10: =S10/$B$13 -> -0.1517655 | AJ10: =T10/$B$13 -> 0.1517655 | AK10: =U10/$B$13 -> -0.20888729 | AL10: =V10/$B$13 -> 0.24556174 | AM10: =W10/$B$13 -> -0.079787845 | AN10: =X10/$B$13 -> 0.25819889 | AO10: =Y10/$B$13 -> 0 | ... AQ10: =AA10/$B$13 -> -0.24556174
A12: total energy | B12: =SUM(AG8:AG10) -> 15
A13: NORM | B13: =SQRT(B12) -> 3.8729833
A14: CHECK SUMSQ(norm comps)=1 | B14: =SUMSQ(AH8:AQ10) -> 1

Sheet sweet
A1: Token "sweet" (slot m=2, 5 cp). Codec, every step.
A2: angle -> Re/Im -> box sums -> |arrow| -> energy -> NORM -> NORMALIZED components (these feed the Squeeze).
C5: ANGLES = -p x step | H5: Re = COS | M5: Im = SIN | R5: BOX SUMS | Z5: |arrow| | AD5: energy | AE5: NORMALIZED components = (Re,Im)/NORM
A6: lens | B6: step | C6: s p=0 | D6: w p=1 | E6: e p=2 | F6: e p=3 | G6: t p=4 | H6: s p=0 | I6: w p=1 | J6: e p=2 | K6: e p=3 | L6: t p=4 | M6: s p=0 | N6: w p=1 | O6: e p=2 | P6: e p=3 | Q6: t p=4 | R6: e Re | S6: e Im | T6: s Re | U6: s Im | V6: t Re | W6: t Im | X6: w Re | Y6: w Im | Z6: e | AA6: s | AB6: t | AC6: w | AD6: sum|a|^2 | AE6: e Re | AF6: e Im | AG6: s Re | AH6: s Im | AI6: t Re | AJ6: t Im | AK6: w Re | AL6: w Im
R7: p=2,3 | T7: p=0 | V7: p=4 | X7: p=1
A8: L0 | B8: =ROUND(Ladder!$B$15,2) -> 162 | C8: =-0*Ladder!$B$15 -> 0 | D8: =-1*Ladder!$B$15 -> -162 | E8: =-2*Ladder!$B$15 -> -324 | F8: =-3*Ladder!$B$15 -> -486 | G8: =-4*Ladder!$B$15 -> -648 | H8: =COS(RADIANS(C8)) -> 1 | I8: =COS(RADIANS(D8)) -> -0.95105652 | J8: =COS(RADIANS(E8)) -> 0.80901699 | K8: =COS(RADIANS(F8)) -> -0.58778525 | L8: =COS(RADIANS(G8)) -> 0.30901699 | M8: =SIN(RADIANS(C8)) -> 0 | N8: =SIN(RADIANS(D8)) -> -0.30901699 | O8: =SIN(RADIANS(E8)) -> 0.58778525 | P8: =SIN(RADIANS(F8)) -> -0.80901699 | Q8: =SIN(RADIANS(G8)) -> 0.95105652 | R8: =J8+K8 -> 0.22123174 | S8: =O8+P8 -> -0.22123174 | T8: =H8 -> 1 | U8: =M8 -> 0 | V8: =L8 -> 0.30901699 | W8: =Q8 -> 0.95105652 | X8: =I8 -> -0.95105652 | Y8: =N8 -> -0.30901699 | Z8: =SQRT(R8^2+S8^2) -> 0.31286893 | AA8: =SQRT(T8^2+U8^2) -> 1 | AB8: =SQRT(V8^2+W8^2) -> 1 | AC8: =SQRT(X8^2+Y8^2) -> 1 | AD8: =SUMSQ(Z8:AC8) -> 3.097887 | AE8: =R8/$B$13 -> 0.055006959 | AF8: =S8/$B$13 -> -0.055006959 | AG8: =T8/$B$13 -> 0.24863954 | AH8: =U8/$B$13 -> 0 | AI8: =V8/$B$13 -> 0.076833844 | AJ8: =W8/$B$13 -> 0.23647026 | AK8: =X8/$B$13 -> -0.23647026 | AL8: =Y8/$B$13 -> -0.076833844
A9: L1 | B9: =ROUND(Ladder!$B$16,2) -> 54 | C9: =-0*Ladder!$B$16 -> 0 | D9: =-1*Ladder!$B$16 -> -54 | E9: =-2*Ladder!$B$16 -> -108 | F9: =-3*Ladder!$B$16 -> -162 | G9: =-4*Ladder!$B$16 -> -216 | H9: =COS(RADIANS(C9)) -> 1 | I9: =COS(RADIANS(D9)) -> 0.58778525 | J9: =COS(RADIANS(E9)) -> -0.30901699 | K9: =COS(RADIANS(F9)) -> -0.95105652 | L9: =COS(RADIANS(G9)) -> -0.80901699 | M9: =SIN(RADIANS(C9)) -> 0 | N9: =SIN(RADIANS(D9)) -> -0.80901699 | O9: =SIN(RADIANS(E9)) -> -0.95105652 | P9: =SIN(RADIANS(F9)) -> -0.30901699 | Q9: =SIN(RADIANS(G9)) -> 0.58778525 | R9: =J9+K9 -> -1.2600735 | S9: =O9+P9 -> -1.2600735 | T9: =H9 -> 1 | U9: =M9 -> 0 | V9: =L9 -> -0.80901699 | W9: =Q9 -> 0.58778525 | X9: =I9 -> 0.58778525 | Y9: =N9 -> -0.80901699 | Z9: =SQRT(R9^2+S9^2) -> 1.782013 | AA9: =SQRT(T9^2+U9^2) -> 1 | AB9: =SQRT(V9^2+W9^2) -> 1 | AC9: =SQRT(X9^2+Y9^2) -> 1 | AD9: =SUMSQ(Z9:AC9) -> 6.1755705 | AE9: =R9/$B$13 -> -0.3133041 | AF9: =S9/$B$13 -> -0.3133041 | AG9: =T9/$B$13 -> 0.24863954 | AH9: =U9/$B$13 -> 0 | AI9: =V9/$B$13 -> -0.20115361 | AJ9: =W9/$B$13 -> 0.14614666 | AK9: =X9/$B$13 -> 0.14614666 | AL9: =Y9/$B$13 -> -0.20115361
A10: L2 | B10: =ROUND(Ladder!$B$17,2) -> 18 | C10: =-0*Ladder!$B$17 -> 0 | D10: =-1*Ladder!$B$17 -> -18 | E10: =-2*Ladder!$B$17 -> -36 | F10: =-3*Ladder!$B$17 -> -54 | G10: =-4*Ladder!$B$17 -> -72 | H10: =COS(RADIANS(C10)) -> 1 | I10: =COS(RADIANS(D10)) -> 0.95105652 | J10: =COS(RADIANS(E10)) -> 0.80901699 | K10: =COS(RADIANS(F10)) -> 0.58778525 | L10: =COS(RADIANS(G10)) -> 0.30901699 | M10: =SIN(RADIANS(C10)) -> 0 | N10: =SIN(RADIANS(D10)) -> -0.30901699 | O10: =SIN(RADIANS(E10)) -> -0.58778525 | P10: =SIN(RADIANS(F10)) -> -0.80901699 | Q10: =SIN(RADIANS(G10)) -> -0.95105652 | R10: =J10+K10 -> 1.3968022 | S10: =O10+P10 -> -1.3968022 | T10: =H10 -> 1 | U10: =M10 -> 0 | V10: =L10 -> 0.30901699 | W10: =Q10 -> -0.95105652 | X10: =I10 -> 0.95105652 | Y10: =N10 -> -0.30901699 | Z10: =SQRT(R10^2+S10^2) -> 1.9753767 | AA10: =SQRT(T10^2+U10^2) -> 1 | AB10: =SQRT(V10^2+W10^2) -> 1 | AC10: =SQRT(X10^2+Y10^2) -> 1 | AD10: =SUMSQ(Z10:AC10) -> 6.902113 | AE10: =R10/$B$13 -> 0.34730027 | AF10: =S10/$B$13 -> -0.34730027 | AG10: =T10/$B$13 -> 0.24863954 | AH10: =U10/$B$13 -> 0 | AI10: =V10/$B$13 -> 0.076833844 | AJ10: =W10/$B$13 -> -0.23647026 | AK10: =X10/$B$13 -> 0.23647026 | AL10: =Y10/$B$13 -> -0.076833844
A12: total energy | B12: =SUM(AD8:AD10) -> 16.175571
A13: NORM | B13: =SQRT(B12) -> 4.0218864
A14: CHECK SUMSQ(norm comps)=1 | B14: =SUMSQ(AE8:AL10) -> 1

Sheet prince
A1: Token "prince" (slot m=3, 6 cp). Codec, every step.
A2: angle -> Re/Im -> box sums -> |arrow| -> energy -> NORM -> NORMALIZED components (these feed the Squeeze).
C5: ANGLES = -p x step | I5: Re = COS | O5: Im = SIN | U5: BOX SUMS | AG5: |arrow| | AM5: energy | AN5: NORMALIZED components = (Re,Im)/NORM
A6: lens | B6: step | C6: p p=0 | D6: r p=1 | E6: i p=2 | F6: n p=3 | G6: c p=4 | H6: e p=5 | I6: p p=0 | J6: r p=1 | K6: i p=2 | L6: n p=3 | M6: c p=4 | N6: e p=5 | O6: p p=0 | P6: r p=1 | Q6: i p=2 | R6: n p=3 | S6: c p=4 | T6: e p=5 | U6: c Re | V6: c Im | W6: e Re | X6: e Im | Y6: i Re | Z6: i Im | AA6: n Re | AB6: n Im | AC6: p Re | AD6: p Im | AE6: r Re | AF6: r Im | AG6: c | AH6: e | AI6: i | AJ6: n | AK6: p | AL6: r | AM6: sum|a|^2 | AN6: c Re | AO6: c Im | AP6: e Re | AQ6: e Im | AR6: i Re | AS6: i Im | AT6: n Re | AU6: n Im | AV6: p Re | AW6: p Im | AX6: r Re | AY6: r Im
U7: p=4 | W7: p=5 | Y7: p=2 | AA7: p=3 | AC7: p=0 | AE7: p=1
A8: L0 | B8: =ROUND(Ladder!$B$15,2) -> 162 | C8: =-0*Ladder!$B$15 -> 0 | D8: =-1*Ladder!$B$15 -> -162 | E8: =-2*Ladder!$B$15 -> -324 | F8: =-3*Ladder!$B$15 -> -486 | G8: =-4*Ladder!$B$15 -> -648 | H8: =-5*Ladder!$B$15 -> -810 | I8: =COS(RADIANS(C8)) -> 1 | J8: =COS(RADIANS(D8)) -> -0.95105652 | K8: =COS(RADIANS(E8)) -> 0.80901699 | L8: =COS(RADIANS(F8)) -> -0.58778525 | M8: =COS(RADIANS(G8)) -> 0.30901699 | N8: =COS(RADIANS(H8)) -> 5.5109106e-16 | O8: =SIN(RADIANS(C8)) -> 0 | P8: =SIN(RADIANS(D8)) -> -0.30901699 | Q8: =SIN(RADIANS(E8)) -> 0.58778525 | R8: =SIN(RADIANS(F8)) -> -0.80901699 | S8: =SIN(RADIANS(G8)) -> 0.95105652 | T8: =SIN(RADIANS(H8)) -> -1 | U8: =M8 -> 0.30901699 | V8: =S8 -> 0.95105652 | W8: =N8 -> 5.5109106e-16 | X8: =T8 -> -1 | Y8: =K8 -> 0.80901699 | Z8: =Q8 -> 0.58778525 | AA8: =L8 -> -0.58778525 | AB8: =R8 -> -0.80901699 | AC8: =I8 -> 1 | AD8: =O8 -> 0 | AE8: =J8 -> -0.95105652 | AF8: =P8 -> -0.30901699 | AG8: =SQRT(U8^2+V8^2) -> 1 | AH8: =SQRT(W8^2+X8^2) -> 1 | AI8: =SQRT(Y8^2+Z8^2) -> 1 | AJ8: =SQRT(AA8^2+AB8^2) -> 1 | AK8: =SQRT(AC8^2+AD8^2) -> 1 | AL8: =SQRT(AE8^2+AF8^2) -> 1 | AM8: =SUMSQ(AG8:AL8) -> 6 | AN8: =U8/$B$13 -> 0.072836004 | AO8: =V8/$B$13 -> 0.22416617 | AP8: =W8/$B$13 -> 1.2989341e-16 | AQ8: =X8/$B$13 -> -0.23570226 | AR8: =Y8/$B$13 -> 0.19068713 | AS8: =Z8/$B$13 -> 0.13854231 | AT8: =AA8/$B$13 -> -0.13854231 | AU8: =AB8/$B$13 -> -0.19068713 | ... AY8: =AF8/$B$13 -> -0.072836004
A9: L1 | B9: =ROUND(Ladder!$B$16,2) -> 54 | C9: =-0*Ladder!$B$16 -> 0 | D9: =-1*Ladder!$B$16 -> -54 | E9: =-2*Ladder!$B$16 -> -108 | F9: =-3*Ladder!$B$16 -> -162 | G9: =-4*Ladder!$B$16 -> -216 | H9: =-5*Ladder!$B$16 -> -270 | I9: =COS(RADIANS(C9)) -> 1 | J9: =COS(RADIANS(D9)) -> 0.58778525 | K9: =COS(RADIANS(E9)) -> -0.30901699 | L9: =COS(RADIANS(F9)) -> -0.95105652 | M9: =COS(RADIANS(G9)) -> -0.80901699 | N9: =COS(RADIANS(H9)) -> 7.044814e-16 | O9: =SIN(RADIANS(C9)) -> 0 | P9: =SIN(RADIANS(D9)) -> -0.80901699 | Q9: =SIN(RADIANS(E9)) -> -0.95105652 | R9: =SIN(RADIANS(F9)) -> -0.30901699 | S9: =SIN(RADIANS(G9)) -> 0.58778525 | T9: =SIN(RADIANS(H9)) -> 1 | U9: =M9 -> -0.80901699 | V9: =S9 -> 0.58778525 | W9: =N9 -> 7.044814e-16 | X9: =T9 -> 1 | Y9: =K9 -> -0.30901699 | Z9: =Q9 -> -0.95105652 | AA9: =L9 -> -0.95105652 | AB9: =R9 -> -0.30901699 | AC9: =I9 -> 1 | AD9: =O9 -> 0 | AE9: =J9 -> 0.58778525 | AF9: =P9 -> -0.80901699 | AG9: =SQRT(U9^2+V9^2) -> 1 | AH9: =SQRT(W9^2+X9^2) -> 1 | AI9: =SQRT(Y9^2+Z9^2) -> 1 | AJ9: =SQRT(AA9^2+AB9^2) -> 1 | AK9: =SQRT(AC9^2+AD9^2) -> 1 | AL9: =SQRT(AE9^2+AF9^2) -> 1 | AM9: =SUMSQ(AG9:AL9) -> 6 | AN9: =U9/$B$13 -> -0.19068713 | AO9: =V9/$B$13 -> 0.13854231 | AP9: =W9/$B$13 -> 1.6604786e-16 | AQ9: =X9/$B$13 -> 0.23570226 | AR9: =Y9/$B$13 -> -0.072836004 | AS9: =Z9/$B$13 -> -0.22416617 | AT9: =AA9/$B$13 -> -0.22416617 | AU9: =AB9/$B$13 -> -0.072836004 | ... AY9: =AF9/$B$13 -> -0.19068713
A10: L2 | B10: =ROUND(Ladder!$B$17,2) -> 18 | C10: =-0*Ladder!$B$17 -> 0 | D10: =-1*Ladder!$B$17 -> -18 | E10: =-2*Ladder!$B$17 -> -36 | F10: =-3*Ladder!$B$17 -> -54 | G10: =-4*Ladder!$B$17 -> -72 | H10: =-5*Ladder!$B$17 -> -90 | I10: =COS(RADIANS(C10)) -> 1 | J10: =COS(RADIANS(D10)) -> 0.95105652 | K10: =COS(RADIANS(E10)) -> 0.80901699 | L10: =COS(RADIANS(F10)) -> 0.58778525 | M10: =COS(RADIANS(G10)) -> 0.30901699 | N10: =COS(RADIANS(H10)) -> -3.8285687e-16 | O10: =SIN(RADIANS(C10)) -> 0 | P10: =SIN(RADIANS(D10)) -> -0.30901699 | Q10: =SIN(RADIANS(E10)) -> -0.58778525 | R10: =SIN(RADIANS(F10)) -> -0.80901699 | S10: =SIN(RADIANS(G10)) -> -0.95105652 | T10: =SIN(RADIANS(H10)) -> -1 | U10: =M10 -> 0.30901699 | V10: =S10 -> -0.95105652 | W10: =N10 -> -3.8285687e-16 | X10: =T10 -> -1 | Y10: =K10 -> 0.80901699 | Z10: =Q10 -> -0.58778525 | AA10: =L10 -> 0.58778525 | AB10: =R10 -> -0.80901699 | AC10: =I10 -> 1 | AD10: =O10 -> 0 | AE10: =J10 -> 0.95105652 | AF10: =P10 -> -0.30901699 | AG10: =SQRT(U10^2+V10^2) -> 1 | AH10: =SQRT(W10^2+X10^2) -> 1 | AI10: =SQRT(Y10^2+Z10^2) -> 1 | AJ10: =SQRT(AA10^2+AB10^2) -> 1 | AK10: =SQRT(AC10^2+AD10^2) -> 1 | AL10: =SQRT(AE10^2+AF10^2) -> 1 | AM10: =SUMSQ(AG10:AL10) -> 6 | AN10: =U10/$B$13 -> 0.072836004 | AO10: =V10/$B$13 -> -0.22416617 | AP10: =W10/$B$13 -> -9.024023e-17 | AQ10: =X10/$B$13 -> -0.23570226 | AR10: =Y10/$B$13 -> 0.19068713 | AS10: =Z10/$B$13 -> -0.13854231 | AT10: =AA10/$B$13 -> 0.13854231 | AU10: =AB10/$B$13 -> -0.19068713 | ... AY10: =AF10/$B$13 -> -0.072836004
A12: total energy | B12: =SUM(AM8:AM10) -> 18
A13: NORM | B13: =SQRT(B12) -> 4.2426407
A14: CHECK SUMSQ(norm comps)=1 | B14: =SUMSQ(AN8:AY10) -> 1

Sheet Squeeze
A1: Squeeze: flatten (78 features) x W (78x8, the ONLY learned object) = 8-dim embedding per token.
A2: Feature order: for each box (union, sorted), for each lens L0..L2, Re then Im. Absent box for a token = structural 0.
A4: feature | B4: good | C4: night | D4: sweet | E4: prince | G4: W col e0 | H4: W col e1 | I4: W col e2 | J4: W col e3 | K4: W col e4 | L4: W col e5 | M4: W col e6 | N4: W col e7
A5: c(0x63) L0 Re | B5: 0 | C5: 0 | D5: 0 | E5: =prince!AN8 -> 0.072836004 | G5: 0.035 | H5: -0.118 | I5: 0.085 | J5: 0.106 | K5: -0.221 | L5: -0.147 | M5: 0.014 | N5: -0.036
A6: c(0x63) L0 Im | B6: 0 | C6: 0 | D6: 0 | E6: =prince!AO8 -> 0.22416617 | G6: -0.002 | H6: -0.097 | I6: 0.1 | J6: 0.088 | K6: 0.007 | L6: 0.128 | M6: 0.053 | N6: -0.097
A7: c(0x63) L1 Re | B7: 0 | C7: 0 | D7: 0 | E7: =prince!AN9 -> -0.19068713 | G7: 0.042 | H7: -0.109 | I7: 0.099 | J7: -0.006 | K7: -0.021 | L7: -0.077 | M7: 0.138 | N7: -0.017
A8: c(0x63) L1 Im | B8: 0 | C8: 0 | D8: 0 | E8: =prince!AO9 -> 0.13854231 | G8: -0.048 | H8: -0.04 | I8: 0.06 | J8: 0.041 | K8: 0.047 | L8: 0.049 | M8: 0.242 | N8: -0.046
A9: c(0x63) L2 Re | B9: 0 | C9: 0 | D9: 0 | E9: =prince!AN10 -> 0.072836004 | G9: -0.058 | H9: -0.092 | I9: 0.07 | J9: 0.128 | K9: -0.013 | L9: -0.095 | M9: -0.093 | N9: 0.074
A10: c(0x63) L2 Im | B10: 0 | C10: 0 | D10: 0 | E10: =prince!AO10 -> -0.22416617 | G10: 0.084 | H10: 0.062 | I10: -0.075 | J10: 0.026 | K10: 0.013 | L10: 0.025 | M10: 0.099 | N10: 0.025
A11: d(0x64) L0 Re | B11: =good!Y8 -> -0.16193248 | C11: 0 | D11: 0 | E11: 0 | G11: 0.077 | H11: 0.008 | I11: 0.033 | J11: 0.071 | K11: -0.165 | L11: -0.036 | M11: -0.053 | N11: -0.072
A12: d(0x64) L0 Im | B12: =good!Z8 -> -0.22288094 | C12: 0 | D12: 0 | E12: 0 | G12: -0.031 | H12: 0.169 | I12: -0.098 | J12: 0.11 | K12: -0.191 | L12: -0.038 | M12: 0.018 | N12: 0.066
A13: d(0x64) L1 Re | B13: =good!Y9 -> -0.26201226 | C13: 0 | D13: 0 | E13: 0 | G13: 0.081 | H13: 0.09 | I13: -0.039 | J13: -0.052 | K13: 0.097 | L13: -0.022 | M13: -0.144 | N13: -0.128
A14: d(0x64) L1 Im | B14: =good!Z9 -> -0.085132943 | C14: 0 | D14: 0 | E14: 0 | G14: -0.104 | H14: 0.056 | I14: 0.016 | J14: 0.078 | K14: -0.048 | L14: 0.018 | M14: 0.071 | N14: -0.035
A15: d(0x64) L2 Re | B15: =good!Y10 -> 0.16193248 | C15: 0 | D15: 0 | E15: 0 | G15: 0.052 | H15: -0.075 | I15: -0.041 | J15: -0.043 | K15: -0.135 | L15: 0.055 | M15: -0.053 | N15: 0.001
A16: d(0x64) L2 Im | B16: =good!Z10 -> -0.22288094 | C16: 0 | D16: 0 | E16: 0 | G16: 0.054 | H16: 0.051 | I16: 0.075 | J16: -0.011 | K16: -0.048 | L16: -0.009 | M16: -0.191 | N16: -0.164
A17: e(0x65) L0 Re | B17: 0 | C17: 0 | D17: =sweet!AE8 -> 0.055006959 | E17: =prince!AP8 -> 1.2989341e-16 | G17: -0.15 | H17: -0.113 | I17: 0.045 | J17: -0.103 | K17: -0.043 | L17: 0.147 | M17: -0.04 | N17: 0.084
A18: e(0x65) L0 Im | B18: 0 | C18: 0 | D18: =sweet!AF8 -> -0.055006959 | E18: =prince!AQ8 -> -0.23570226 | G18: -0.106 | H18: -0.023 | I18: -0.108 | J18: -0.038 | K18: 0.095 | L18: -0.196 | M18: 0.049 | N18: 0.027
A19: e(0x65) L1 Re | B19: 0 | C19: 0 | D19: =sweet!AE9 -> -0.3133041 | E19: =prince!AP9 -> 1.6604786e-16 | G19: -0.067 | H19: -0.164 | I19: 0.008 | J19: -0.06 | K19: 0.026 | L19: 0.002 | M19: 0.181 | N19: -0.027
A20: e(0x65) L1 Im | B20: 0 | C20: 0 | D20: =sweet!AF9 -> -0.3133041 | E20: =prince!AQ9 -> 0.23570226 | G20: -0.116 | H20: 0.02 | I20: 0.025 | J20: 0.154 | K20: 0.095 | L20: 0.04 | M20: 0.166 | N20: -0.135
A21: e(0x65) L2 Re | B21: 0 | C21: 0 | D21: =sweet!AE10 -> 0.34730027 | E21: =prince!AP10 -> -9.024023e-17 | G21: -0.072 | H21: -0.105 | I21: -0.044 | J21: -0.156 | K21: 0.072 | L21: -0.025 | M21: -0.167 | N21: -0.115
A22: e(0x65) L2 Im | B22: 0 | C22: 0 | D22: =sweet!AF10 -> -0.34730027 | E22: =prince!AQ10 -> -0.23570226 | G22: 0.035 | H22: 0.095 | I22: 0.226 | J22: 0.33 | K22: 0.047 | L22: -0.112 | M22: -0.241 | N22: 0.03
A23: g(0x67) L0 Re | B23: =good!AA8 -> 0.27549599 | C23: =night!AH8 -> 0.20888729 | D23: 0 | E23: 0 | G23: -0.092 | H23: -0.047 | I23: -0.069 | J23: -0.016 | K23: 0.121 | L23: 0.018 | M23: -0.018 | N23: -0.117
A24: g(0x67) L0 Im | B24: =good!AB8 -> 0 | C24: =night!AI8 -> 0.1517655 | D24: 0 | E24: 0 | G24: -0.19 | H24: -0.055 | I24: -0.006 | J24: 0.2 | K24: 0.015 | L24: 0.111 | M24: -0.057 | N24: -0.134
A25: g(0x67) L1 Re | B25: =good!AA9 -> 0.27549599 | C25: =night!AH9 -> -0.079787845 | D25: 0 | E25: 0 | G25: -0.109 | H25: -0.082 | I25: 0.241 | J25: -0.093 | K25: 0.095 | L25: -0.102 | M25: 0.105 | N25: 0.044
A26: g(0x67) L1 Im | B26: =good!AB9 -> 0 | C26: =night!AI9 -> -0.24556174 | D26: 0 | E26: 0 | G26: -0.018 | H26: -0.005 | I26: -0.074 | J26: 0.051 | K26: -0.052 | L26: -0.139 | M26: -0.145 | N26: 0.02
A27: g(0x67) L2 Re | B27: =good!AA10 -> 0.27549599 | C27: =night!AH10 -> 0.20888729 | D27: 0 | E27: 0 | G27: 0.179 | H27: 0.018 | I27: -0.013 | J27: 0.032 | K27: 0.148 | L27: 0.025 | M27: -0.047 | N27: 0.125
A28: g(0x67) L2 Im | B28: =good!AB10 -> 0 | C28: =night!AI10 -> -0.1517655 | D28: 0 | E28: 0 | G28: 0.049 | H28: 0.174 | I28: 0.021 | J28: -0.139 | K28: -0.155 | L28: 0.187 | M28: 0.195 | N28: -0.02
A29: h(0x68) L0 Re | B29: 0 | C29: =night!AJ8 -> -0.1517655 | D29: 0 | E29: 0 | G29: -0.043 | H29: 0.165 | I29: -0.125 | J29: -0.101 | K29: 0.073 | L29: -0.045 | M29: -0.001 | N29: -0.019
A30: h(0x68) L0 Im | B30: 0 | C30: =night!AK8 -> -0.20888729 | D30: 0 | E30: 0 | G30: 0.038 | H30: 0.159 | I30: 0.01 | J30: 0.073 | K30: -0.232 | L30: -0.006 | M30: -0.095 | N30: -0.138
A31: h(0x68) L1 Re | B31: 0 | C31: =night!AJ9 -> -0.24556174 | D31: 0 | E31: 0 | G31: -0.099 | H31: -0.038 | I31: 0.104 | J31: -0.15 | K31: 0.003 | L31: -0.055 | M31: -0.037 | N31: 0.114
A32: h(0x68) L1 Im | B32: 0 | C32: =night!AK9 -> -0.079787845 | D32: 0 | E32: 0 | G32: 0.061 | H32: 0.151 | I32: -0.017 | J32: -0.079 | K32: -0.025 | L32: 0.027 | M32: 0.02 | N32: -0.123
A33: h(0x68) L2 Re | B33: 0 | C33: =night!AJ10 -> 0.1517655 | D33: 0 | E33: 0 | G33: 0.01 | H33: 0.026 | I33: 0.285 | J33: 0.213 | K33: -0.097 | L33: -0.033 | M33: -0.166 | N33: -0.067
A34: h(0x68) L2 Im | B34: 0 | C34: =night!AK10 -> -0.20888729 | D34: 0 | E34: 0 | G34: 0.036 | H34: 0.137 | I34: -0.083 | J34: -0.074 | K34: -0.243 | L34: -0.018 | M34: -0.12 | N34: -0.06
A35: i(0x69) L0 Re | B35: 0 | C35: =night!AL8 -> -0.24556174 | D35: 0 | E35: =prince!AR8 -> 0.19068713 | G35: -0.099 | H35: -0.011 | I35: -0.199 | J35: -0.166 | K35: 0.241 | L35: -0.146 | M35: -0.124 | N35: 0.208
A36: i(0x69) L0 Im | B36: 0 | C36: =night!AM8 -> -0.079787845 | D36: 0 | E36: =prince!AS8 -> 0.13854231 | G36: 0.329 | H36: -0.133 | I36: -0.042 | J36: 0.039 | K36: 0.196 | L36: -0.112 | M36: -0.028 | N36: 0.088
A37: i(0x69) L1 Re | B37: 0 | C37: =night!AL9 -> 0.1517655 | D37: 0 | E37: =prince!AR9 -> -0.072836004 | G37: 0.049 | H37: -0.043 | I37: -0.015 | J37: -0.156 | K37: -0.027 | L37: -0.03 | M37: 0.026 | N37: -0.063
A38: i(0x69) L1 Im | B38: 0 | C38: =night!AM9 -> -0.20888729 | D38: 0 | E38: =prince!AS9 -> -0.22416617 | G38: 0.053 | H38: 0.115 | I38: 0.018 | J38: 0.04 | K38: 0.006 | L38: 0 | M38: -0.082 | N38: 0.036
A39: i(0x69) L2 Re | B39: 0 | C39: =night!AL10 -> 0.24556174 | D39: 0 | E39: =prince!AR10 -> 0.19068713 | G39: -0.011 | H39: 0.237 | I39: 0.178 | J39: 0.044 | K39: -0.086 | L39: -0.126 | M39: 0.135 | N39: 0.03
A40: i(0x69) L2 Im | B40: 0 | C40: =night!AM10 -> -0.079787845 | D40: 0 | E40: =prince!AS10 -> -0.13854231 | G40: 0.054 | H40: -0.198 | I40: 0.105 | J40: 0.051 | K40: -0.126 | L40: -0.053 | M40: 0.03 | N40: 0.006
A41: n(0x6E) L0 Re | B41: 0 | C41: =night!AN8 -> 0.25819889 | D41: 0 | E41: =prince!AT8 -> -0.13854231 | G41: -0.033 | H41: -0.012 | I41: -0.029 | J41: 0.017 | K41: 0.167 | L41: -0.291 | M41: -0.027 | N41: 0.02
...

Sheet Twist
A1: Slot twist: embedding read as 4 pairs; pair j of token at slot m rotates by theta_j x m.
A2: new Re = Re*cos - Im*sin ; new Im = Re*sin + Im*cos. m=0 -> untouched. Lengths never change (bottom check).
A4: token | B4: m | C4: pair0 Re | D4: pair0 Im | E4: pair1 Re | F4: pair1 Im | G4: pair2 Re | H4: pair2 Im | I4: pair3 Re | J4: pair3 Im
A5: BEFORE (from Squeeze)
A6: good | B6: 0 | C6: =Squeeze!B86 -> 0.0095099061 | D6: =Squeeze!B87 -> -0.051894746 | E6: =Squeeze!B88 -> -0.054449502 | F6: =Squeeze!B89 -> 0.093456422 | G6: =Squeeze!B90 -> 0.18639809 | H6: =Squeeze!B91 -> -0.04489817 | I6: =Squeeze!B92 -> 0.19264789 | J6: =Squeeze!B93 -> 0.29692457
A7: night | B7: 1 | C7: =Squeeze!C86 -> -0.010195182 | D7: =Squeeze!C87 -> -0.018840925 | E7: =Squeeze!C88 -> 0.094171942 | F7: =Squeeze!C89 -> 0.20046777 | G7: =Squeeze!C90 -> 0.10416299 | H7: =Squeeze!C91 -> 0.047643142 | I7: =Squeeze!C92 -> 0.024261217 | J7: =Squeeze!C93 -> -0.053481485
A8: sweet | B8: 2 | C8: =Squeeze!D86 -> -0.11631465 | D8: =Squeeze!D87 -> 0.025968025 | E8: =Squeeze!D88 -> -0.21622299 | F8: =Squeeze!D89 -> -0.23531563 | G8: =Squeeze!D90 -> -0.023866893 | H8: =Squeeze!D91 -> 0.046918561 | I8: =Squeeze!D92 -> -0.16612599 | J8: =Squeeze!D93 -> -0.016185135
A9: prince | B9: 3 | C9: =Squeeze!E86 -> -0.066983151 | D9: =Squeeze!E87 -> 0.096522176 | E9: =Squeeze!E88 -> 0.0036509178 | F9: =Squeeze!E89 -> 0.042608495 | G9: =Squeeze!E90 -> 0.10644746 | H9: =Squeeze!E91 -> 0.12740008 | I9: =Squeeze!E92 -> -0.020996945 | J9: =Squeeze!E93 -> -0.00017411891
A11: AFTER twist (each pair rotated by theta_j x m)
A12: good | B12: =B6 -> 0 | C12: =C6*COS(RADIANS(Ladder!$B$20*$B12))-D6*SIN(RADIANS(Ladder!$B$20*$B12)) -> 0.0095099061 | D12: =C6*SIN(RADIANS(Ladder!$B$20*$B12))+D6*COS(RADIANS(Ladder!$B$20*$B12)) -> -0.051894746 | E12: =E6*COS(RADIANS(Ladder!$B$21*$B12))-F6*SIN(RADIANS(Ladder!$B$21*$B12)) -> -0.054449502 | F12: =E6*SIN(RADIANS(Ladder!$B$21*$B12))+F6*COS(RADIANS(Ladder!$B$21*$B12)) -> 0.093456422 | G12: =G6*COS(RADIANS(Ladder!$B$22*$B12))-H6*SIN(RADIANS(Ladder!$B$22*$B12)) -> 0.18639809 | H12: =G6*SIN(RADIANS(Ladder!$B$22*$B12))+H6*COS(RADIANS(Ladder!$B$22*$B12)) -> -0.04489817 | I12: =I6*COS(RADIANS(Ladder!$B$23*$B12))-J6*SIN(RADIANS(Ladder!$B$23*$B12)) -> 0.19264789 | J12: =I6*SIN(RADIANS(Ladder!$B$23*$B12))+J6*COS(RADIANS(Ladder!$B$23*$B12)) -> 0.29692457
A13: night | B13: =B7 -> 1 | C13: =C7*COS(RADIANS(Ladder!$B$20*$B13))-D7*SIN(RADIANS(Ladder!$B$20*$B13)) -> 0.01551836 | D13: =C7*SIN(RADIANS(Ladder!$B$20*$B13))+D7*COS(RADIANS(Ladder!$B$20*$B13)) -> 0.0147683 | E13: =E7*COS(RADIANS(Ladder!$B$21*$B13))-F7*SIN(RADIANS(Ladder!$B$21*$B13)) -> -0.14654446 | F13: =E7*SIN(RADIANS(Ladder!$B$21*$B13))+F7*COS(RADIANS(Ladder!$B$21*$B13)) -> 0.16607348 | G13: =G7*COS(RADIANS(Ladder!$B$22*$B13))-H7*SIN(RADIANS(Ladder!$B$22*$B13)) -> 0.07059952 | H13: =G7*SIN(RADIANS(Ladder!$B$22*$B13))+H7*COS(RADIANS(Ladder!$B$22*$B13)) -> 0.090197034 | I13: =I7*COS(RADIANS(Ladder!$B$23*$B13))-J7*SIN(RADIANS(Ladder!$B$23*$B13)) -> 0.034228764 | J13: =I7*SIN(RADIANS(Ladder!$B$23*$B13))+J7*COS(RADIANS(Ladder!$B$23*$B13)) -> -0.047720725
A14: sweet | B14: =B8 -> 2 | C14: =C8*COS(RADIANS(Ladder!$B$20*$B14))-D8*SIN(RADIANS(Ladder!$B$20*$B14)) -> -0.078836902 | D14: =C8*SIN(RADIANS(Ladder!$B$20*$B14))+D8*COS(RADIANS(Ladder!$B$20*$B14)) -> 0.089376607 | E14: =E8*COS(RADIANS(Ladder!$B$21*$B14))-F8*SIN(RADIANS(Ladder!$B$21*$B14)) -> 0.31955399 | F14: =E8*SIN(RADIANS(Ladder!$B$21*$B14))+F8*COS(RADIANS(Ladder!$B$21*$B14)) -> 0.0033279491 | G14: =G8*COS(RADIANS(Ladder!$B$22*$B14))-H8*SIN(RADIANS(Ladder!$B$22*$B14)) -> -0.05208896 | H14: =G8*SIN(RADIANS(Ladder!$B$22*$B14))+H8*COS(RADIANS(Ladder!$B$22*$B14)) -> 0.0075973819 | I14: =I8*COS(RADIANS(Ladder!$B$23*$B14))-J8*SIN(RADIANS(Ladder!$B$23*$B14)) -> -0.14728662 | J14: =I8*SIN(RADIANS(Ladder!$B$23*$B14))+J8*COS(RADIANS(Ladder!$B$23*$B14)) -> -0.078526778
A15: prince | B15: =B9 -> 3 | C15: =C9*COS(RADIANS(Ladder!$B$20*$B15))-D9*SIN(RADIANS(Ladder!$B$20*$B15)) -> -0.038716373 | D15: =C9*SIN(RADIANS(Ladder!$B$20*$B15))+D9*COS(RADIANS(Ladder!$B$20*$B15)) -> -0.11092482 | E15: =E9*COS(RADIANS(Ladder!$B$21*$B15))-F9*SIN(RADIANS(Ladder!$B$21*$B15)) -> 0.010971474 | F15: =E9*SIN(RADIANS(Ladder!$B$21*$B15))+F9*COS(RADIANS(Ladder!$B$21*$B15)) -> -0.041333278 | G15: =G9*COS(RADIANS(Ladder!$B$22*$B15))-H9*SIN(RADIANS(Ladder!$B$22*$B15)) -> -0.11158123 | H15: =G9*SIN(RADIANS(Ladder!$B$22*$B15))+H9*COS(RADIANS(Ladder!$B$22*$B15)) -> 0.12292872 | I15: =I9*COS(RADIANS(Ladder!$B$23*$B15))-J9*SIN(RADIANS(Ladder!$B$23*$B15)) -> -0.017361587 | J15: =I9*SIN(RADIANS(Ladder!$B$23*$B15))+J9*COS(RADIANS(Ladder!$B$23*$B15)) -> -0.011810052
A17: CHECK: pair lengths unchanged by twist, token "sweet":
A18: pair | B18: len before | C18: len after
A19: pair0 | B19: =SQRT(C8^2+D8^2) -> 0.11917816 | C19: =SQRT(C14^2+D14^2) -> 0.11917816
A20: pair1 | B20: =SQRT(E8^2+F8^2) -> 0.31957131 | C20: =SQRT(E14^2+F14^2) -> 0.31957131
A21: pair2 | B21: =SQRT(G8^2+H8^2) -> 0.052640098 | C21: =SQRT(G14^2+H14^2) -> 0.052640098
A22: pair3 | B22: =SQRT(I8^2+J8^2) -> 0.16691256 | C22: =SQRT(I14^2+J14^2) -> 0.16691256

Sheet Payoff
A1: Payoff: the SAME token (sweet) twisted at different slots, then dot-producted. Only the GAP m-n matters.
A2: Rows: sweet twisted at m = 2, 5, 7, 10, 3. Scores: (2,5) and (7,10) are gap 3 -> IDENTICAL. (2,3) is gap 1 -> different.
A4: m | B4: pair0 Re | C4: pair0 Im | D4: pair1 Re | E4: pair1 Im | F4: pair2 Re | G4: pair2 Im | H4: pair3 Re | I4: pair3 Im
A5: 2 | B5: =Twist!C8*COS(RADIANS(Ladder!$B$20*$A5))-Twist!D8*SIN(RADIANS(Ladder!$B$20*$A5)) -> -0.078836902 | C5: =Twist!C8*SIN(RADIANS(Ladder!$B$20*$A5))+Twist!D8*COS(RADIANS(Ladder!$B$20*$A5)) -> 0.089376607 | D5: =Twist!E8*COS(RADIANS(Ladder!$B$21*$A5))-Twist!F8*SIN(RADIANS(Ladder!$B$21*$A5)) -> 0.31955399 | E5: =Twist!E8*SIN(RADIANS(Ladder!$B$21*$A5))+Twist!F8*COS(RADIANS(Ladder!$B$21*$A5)) -> 0.0033279491 | F5: =Twist!G8*COS(RADIANS(Ladder!$B$22*$A5))-Twist!H8*SIN(RADIANS(Ladder!$B$22*$A5)) -> -0.05208896 | G5: =Twist!G8*SIN(RADIANS(Ladder!$B$22*$A5))+Twist!H8*COS(RADIANS(Ladder!$B$22*$A5)) -> 0.0075973819 | H5: =Twist!I8*COS(RADIANS(Ladder!$B$23*$A5))-Twist!J8*SIN(RADIANS(Ladder!$B$23*$A5)) -> -0.14728662 | I5: =Twist!I8*SIN(RADIANS(Ladder!$B$23*$A5))+Twist!J8*COS(RADIANS(Ladder!$B$23*$A5)) -> -0.078526778
A6: 5 | B6: =Twist!C8*COS(RADIANS(Ladder!$B$20*$A6))-Twist!D8*SIN(RADIANS(Ladder!$B$20*$A6)) -> -0.025968025 | C6: =Twist!C8*SIN(RADIANS(Ladder!$B$20*$A6))+Twist!D8*COS(RADIANS(Ladder!$B$20*$A6)) -> -0.11631465 | D6: =Twist!E8*COS(RADIANS(Ladder!$B$21*$A6))-Twist!F8*SIN(RADIANS(Ladder!$B$21*$A6)) -> -0.29960641 | E6: =Twist!E8*SIN(RADIANS(Ladder!$B$21*$A6))+Twist!F8*COS(RADIANS(Ladder!$B$21*$A6)) -> -0.11118373 | F6: =Twist!G8*COS(RADIANS(Ladder!$B$22*$A6))-Twist!H8*SIN(RADIANS(Ladder!$B$22*$A6)) -> -0.01467604 | G6: =Twist!G8*SIN(RADIANS(Ladder!$B$22*$A6))+Twist!H8*COS(RADIANS(Ladder!$B$22*$A6)) -> -0.050552881 | H6: =Twist!I8*COS(RADIANS(Ladder!$B$23*$A6))-Twist!J8*SIN(RADIANS(Ladder!$B$23*$A6)) -> -0.078837206 | I6: =Twist!I8*SIN(RADIANS(Ladder!$B$23*$A6))+Twist!J8*COS(RADIANS(Ladder!$B$23*$A6)) -> -0.14712069
A7: 7 | B7: =Twist!C8*COS(RADIANS(Ladder!$B$20*$A7))-Twist!D8*SIN(RADIANS(Ladder!$B$20*$A7)) -> -0.089376607 | C7: =Twist!C8*SIN(RADIANS(Ladder!$B$20*$A7))+Twist!D8*COS(RADIANS(Ladder!$B$20*$A7)) -> -0.078836902 | D7: =Twist!E8*COS(RADIANS(Ladder!$B$21*$A7))-Twist!F8*SIN(RADIANS(Ladder!$B$21*$A7)) -> 0.28608316 | E7: =Twist!E8*SIN(RADIANS(Ladder!$B$21*$A7))+Twist!F8*COS(RADIANS(Ladder!$B$21*$A7)) -> -0.14241576 | F7: =Twist!G8*COS(RADIANS(Ladder!$B$22*$A7))-Twist!H8*SIN(RADIANS(Ladder!$B$22*$A7)) -> 0.032806062 | G7: =Twist!G8*SIN(RADIANS(Ladder!$B$22*$A7))+Twist!H8*COS(RADIANS(Ladder!$B$22*$A7)) -> -0.041167247 | H7: =Twist!I8*COS(RADIANS(Ladder!$B$23*$A7))-Twist!J8*SIN(RADIANS(Ladder!$B$23*$A7)) -> -0.016535431 | I7: =Twist!I8*SIN(RADIANS(Ladder!$B$23*$A7))+Twist!J8*COS(RADIANS(Ladder!$B$23*$A7)) -> -0.16609149
A8: 10 | B8: =Twist!C8*COS(RADIANS(Ladder!$B$20*$A8))-Twist!D8*SIN(RADIANS(Ladder!$B$20*$A8)) -> 0.11631465 | C8: =Twist!C8*SIN(RADIANS(Ladder!$B$20*$A8))+Twist!D8*COS(RADIANS(Ladder!$B$20*$A8)) -> -0.025968025 | D8: =Twist!E8*COS(RADIANS(Ladder!$B$21*$A8))-Twist!F8*SIN(RADIANS(Ladder!$B$21*$A8)) -> -0.31738786 | E8: =Twist!E8*SIN(RADIANS(Ladder!$B$21*$A8))+Twist!F8*COS(RADIANS(Ladder!$B$21*$A8)) -> 0.037293012 | F8: =Twist!G8*COS(RADIANS(Ladder!$B$22*$A8))-Twist!H8*SIN(RADIANS(Ladder!$B$22*$A8)) -> 0.045281006 | G8: =Twist!G8*SIN(RADIANS(Ladder!$B$22*$A8))+Twist!H8*COS(RADIANS(Ladder!$B$22*$A8)) -> 0.026844189 | H8: =Twist!I8*COS(RADIANS(Ladder!$B$23*$A8))-Twist!J8*SIN(RADIANS(Ladder!$B$23*$A8)) -> 0.078526778 | I8: =Twist!I8*SIN(RADIANS(Ladder!$B$23*$A8))+Twist!J8*COS(RADIANS(Ladder!$B$23*$A8)) -> -0.14728662
A9: 3 | B9: =Twist!C8*COS(RADIANS(Ladder!$B$20*$A9))-Twist!D8*SIN(RADIANS(Ladder!$B$20*$A9)) -> 0.047359459 | C9: =Twist!C8*SIN(RADIANS(Ladder!$B$20*$A9))+Twist!D8*COS(RADIANS(Ladder!$B$20*$A9)) -> -0.10936415 | D9: =Twist!E8*COS(RADIANS(Ladder!$B$21*$A9))-Twist!F8*SIN(RADIANS(Ladder!$B$21*$A9)) -> 0.12391906 | E9: =Twist!E8*SIN(RADIANS(Ladder!$B$21*$A9))+Twist!F8*COS(RADIANS(Ladder!$B$21*$A9)) -> 0.2945673 | F9: =Twist!G8*COS(RADIANS(Ladder!$B$22*$A9))-Twist!H8*SIN(RADIANS(Ladder!$B$22*$A9)) -> -0.049750734 | G9: =Twist!G8*SIN(RADIANS(Ladder!$B$22*$A9))+Twist!H8*COS(RADIANS(Ladder!$B$22*$A9)) -> -0.01720013 | H9: =Twist!I8*COS(RADIANS(Ladder!$B$23*$A9))-Twist!J8*SIN(RADIANS(Ladder!$B$23*$A9)) -> -0.12913673 | I9: =Twist!I8*SIN(RADIANS(Ladder!$B$23*$A9))+Twist!J8*COS(RADIANS(Ladder!$B$23*$A9)) -> -0.1057521
A11: score(m=2, n=5) gap 3 | B11: =SUMPRODUCT(B5:I5,B6:I6) -> -0.080914037 | C11: these two...
A12: score(m=7, n=10) gap 3 | B12: =SUMPRODUCT(B7:I7,B8:I8) -> -0.080914037 | C12: ...are identical
A13: score(m=2, n=3) gap 1 | B13: =SUMPRODUCT(B5:I5,B9:I9) -> 0.056856136 | C13: different gap, different score
A15: Lengths equal everywhere (identity); phases differ only via theta_j x (m-n): absolute slots cancelled.
